Workbook
Name CategoryList: #REF!

Sheet Transactions
A1: Date | B1: Description | C1: Type (IN/OUT) | D1: Amount (Excl. VAT) | E1: Account | F1: Category | G1: Project | H1: Material Item | I1: Qty | J1: Rate | K1: Party Name | L1: Party Type | M1: Invoice # | N1: Tax % | O1: Tax Amount | P1: Total Amount | Q1: Payment Status | R1: Notes
A2: 45965 | B2: chemicals | C2: OUT | D2: 220 | E2: Cash | F2: Material Purchase | G2: SS316 Pipeline Work | H2: Material/Tools | K2: TBD | L2: Supplier | N2: 15 | O2: =IF(OR(D2="", N2=""), "", ROUND(D2 * N2 / 100, 2)) -> 33 | P2: =IF(D2="", "", D2 + O2) -> 253 | Q2: Paid
A3: 45965 | B3: Chemicals | C3: OUT | D3: 169.5 | E3: Cash | F3: Material Purchase | G3: SS316 Pipeline Work | H3: Material/Tools | K3: TBD | L3: Supplier | N3: 15 | O3: =IF(OR(D3="", N3=""), "", ROUND(D3 * N3 / 100, 2)) -> 25.43 | P3: =IF(D3="", "", D3 + O3) -> 194.93 | Q3: Paid
A4: 45965 | B4: SS316 albo | C4: OUT | D4: 269.57 | E4: Cash | F4: Material Purchase | G4: SS316 Pipeline Work | H4: Material/Tools | K4: TBD | L4: Supplier | N4: 15 | O4: =IF(OR(D4="", N4=""), "", ROUND(D4 * N4 / 100, 2)) -> 40.44 | P4: =IF(D4="", "", D4 + O4) -> 310.01 | Q4: Paid
A5: 45965 | B5: SS316 plastic raw material | C5: OUT | D5: 473.91 | E5: Cash | F5: Material Purchase | G5: SS316 Pipeline Work | H5: Material/Tools | K5: TBD | L5: Supplier | N5: 15 | O5: =IF(OR(D5="", N5=""), "", ROUND(D5 * N5 / 100, 2)) -> 71.09 | P5: =IF(D5="", "", D5 + O5) -> 545 | Q5: Paid
A6: 45966 | B6: Welding machine | C6: OUT | D6: 1808.7 | E6: Cash | F6: Equipment Purchase | G6: SS316 Pipeline Work | H6: Material/Tools | K6: TBD | L6: Supplier | N6: 15 | O6: =IF(OR(D6="", N6=""), "", ROUND(D6 * N6 / 100, 2)) -> 271.31 | P6: =IF(D6="", "", D6 + O6) -> 2080.01 | Q6: Paid
A7: 45966 | B7: Food for team | C7: OUT | D7: 217.39 | E7: Cash | F7: Food Expense | G7: SS316 Pipeline Work | H7: Food for Team | K7: TBD | L7: Supplier | N7: 15 | O7: =IF(OR(D7="", N7=""), "", ROUND(D7 * N7 / 100, 2)) -> 32.61 | P7: =IF(D7="", "", D7 + O7) -> 250 | Q7: Paid
A8: 45966 | B8: Labour charges 2 days | C8: OUT | D8: 886.96 | E8: Cash | F8: Labour Expense | G8: SS316 Pipeline Work | H8: Labour Chares | K8: TBD | L8: Supplier | N8: 15 | O8: =IF(OR(D8="", N8=""), "", ROUND(D8 * N8 / 100, 2)) -> 133.04 | P8: =IF(D8="", "", D8 + O8) -> 1020 | Q8: Paid
A9: 45966 | B9: Petrol for project | C9: OUT | D9: 301.74 | E9: Cash | F9: Fuel Expense | G9: SS316 Pipeline Work | H9: Fuel Expense | K9: TBD | L9: Supplier | N9: 15 | O9: =IF(OR(D9="", N9=""), "", ROUND(D9 * N9 / 100, 2)) -> 45.26 | P9: =IF(D9="", "", D9 + O9) -> 347 | Q9: Paid
A10: 45966 | B10: SS316 pipes 18m | C10: OUT | D10: 434.78 | E10: Cash | F10: Material Purchase | G10: SS316 Pipeline Work | H10: Material/Tools | K10: TBD | L10: Supplier | N10: 15 | O10: =IF(OR(D10="", N10=""), "", ROUND(D10 * N10 / 100, 2)) -> 65.22 | P10: =IF(D10="", "", D10 + O10) -> 500 | Q10: Paid
A11: 45966 | B11: Invoice raised for SS316 Pipeline Work | C11: IN | D11: 4000 | E11: Cash | F11: Project Income | G11: SS316 Pipeline Work | H11: N/A | K11: Oud Lover Factory | L11: Client | M11: INV/2025/00041 | N11: 15 | O11: =IF(OR(D11="", N11=""), "", ROUND(D11 * N11 / 100, 2)) -> 600 | P11: =IF(D11="", "", D11 + O11) -> 4600 | Q11: Paid | R11: 100% Payment Received
A12: 45967 | B12: Invoice Raised for Instlattion of Sign Board | C12: IN | D12: 2000 | E12: Cash | F12: Project Income | G12: Instalation of Sign Board | H12: N/A | I12: 1 | K12: Feedco Investment Company | L12: Client | M12: INV/2025/00044 | N12: 15 | O12: =IF(OR(D12="", N12=""), "", ROUND(D12 * N12 / 100, 2)) -> 300 | P12: =IF(D12="", "", D12 + O12) -> 2300 | Q12: Paid | R12: 100% Payment Received
A13: 45967 | B13: Net/Bolts | C13: OUT | D13: 104.35 | E13: Cash | F13: Material Purchase | G13: Instalation of Sign Board | H13: Material/Tools | K13: TBD | L13: Supplier | N13: 15 | O13: =IF(OR(D13="", N13=""), "", ROUND(D13 * N13 / 100, 2)) -> 15.65 | P13: =IF(D13="", "", D13 + O13) -> 120 | Q13: Paid
A14: 45967 | B14: Drill Machine | C14: OUT | D14: 417.39 | E14: Cash | F14: Equipment Purchase | G14: Instalation of Sign Board | H14: Material/Tools | K14: TBD | L14: Supplier | N14: 15 | O14: =IF(OR(D14="", N14=""), "", ROUND(D14 * N14 / 100, 2)) -> 62.61 | P14: =IF(D14="", "", D14 + O14) -> 480 | Q14: Paid
A15: 45967 | B15: Food for team | C15: OUT | D15: 139.13 | E15: Cash | F15: Food Expense | G15: Instalation of Sign Board | H15: Food for Team | K15: TBD | L15: Supplier | N15: 15 | O15: =IF(OR(D15="", N15=""), "", ROUND(D15 * N15 / 100, 2)) -> 20.87 | P15: =IF(D15="", "", D15 + O15) -> 160 | Q15: Paid
A16: 45967 | B16: Petrol for project | C16: OUT | D16: 113.04 | E16: Cash | F16: Fuel Expense | G16: Instalation of Sign Board | H16: Fuel Expense | K16: TBD | L16: Supplier | N16: 15 | O16: =IF(OR(D16="", N16=""), "", ROUND(D16 * N16 / 100, 2)) -> 16.96 | P16: =IF(D16="", "", D16 + O16) -> 130 | Q16: Paid
A17: 45970 | B17: 50% advance receive (net only/no VAT) | C17: IN | D17: 7425 | E17: Cash | F17: Project Income | G17: Fabrication of Steel Ramp | H17: N/A | I17: 1 | K17: Bahri Logistics | L17: Client | N17: 0 | O17: =IF(OR(D17="", N17=""), "", ROUND(D17 * N17 / 100, 2)) -> 0 | P17: =IF(D17="", "", D17 + O17) -> 7425 | Q17: Partially Paid | R17: only Project Advance, 50% received, (VAT 100% pending)
A18: 45971 | B18: Industrial lights & bolts | C18: OUT | D18: 170.43 | E18: Cash | F18: Equipment Purchase | G18: Fabrication of Steel Ramp | H18: Material/Tools | K18: TBD | L18: Supplier | N18: 15 | O18: =IF(OR(D18="", N18=""), "", ROUND(D18 * N18 / 100, 2)) -> 25.56 | P18: =IF(D18="", "", D18 + O18) -> 195.99 | Q18: Paid
A19: 45971 | B19: Steel material | C19: OUT | D19: 170.43 | E19: Cash | F19: Material Purchase | G19: Fabrication of Steel Ramp | H19: Material/Tools | K19: TBD | L19: Supplier | N19: 15 | O19: =IF(OR(D19="", N19=""), "", ROUND(D19 * N19 / 100, 2)) -> 25.56 | P19: =IF(D19="", "", D19 + O19) -> 195.99 | Q19: Paid
A20: 45972 | B20: Steel sheet 4mm*6m | C20: OUT | D20: 1095.65 | E20: Cash | F20: Material Purchase | G20: Fabrication of Steel Ramp | H20: Material/Tools | K20: TBD | L20: Supplier | N20: 15 | O20: =IF(OR(D20="", N20=""), "", ROUND(D20 * N20 / 100, 2)) -> 164.35 | P20: =IF(D20="", "", D20 + O20) -> 1260 | Q20: Paid
A21: 45972 | B21: Crane transport | C21: OUT | D21: 695.65 | E21: Cash | F21: Transport Expense | G21: Fabrication of Steel Ramp | H21: Transport | K21: TBD | L21: Supplier | N21: 15 | O21: =IF(OR(D21="", N21=""), "", ROUND(D21 * N21 / 100, 2)) -> 104.35 | P21: =IF(D21="", "", D21 + O21) -> 800 | Q21: Paid
A22: 45973 | B22: Chenku sheet | C22: OUT | D22: 1078.26 | E22: Cash | F22: Material Purchase | G22: Fabrication of Steel Ramp | H22: Material/Tools | K22: TBD | L22: Supplier | N22: 15 | O22: =IF(OR(D22="", N22=""), "", ROUND(D22 * N22 / 100, 2)) -> 161.74 | P22: =IF(D22="", "", D22 + O22) -> 1240 | Q22: Paid
A23: 45973 | B23: Welding rods / grinding / paint | C23: OUT | D23: 330.43 | E23: Cash | F23: Equipment Purchase | G23: Fabrication of Steel Ramp | H23: Material/Tools | K23: TBD | L23: Supplier | N23: 15 | O23: =IF(OR(D23="", N23=""), "", ROUND(D23 * N23 / 100, 2)) -> 49.56 | P23: =IF(D23="", "", D23 + O23) -> 379.99 | Q23: Paid
A24: 45974 | B24: Food for team | C24: OUT | D24: 434.78 | E24: Cash | F24: Food Expense | G24: Fabrication of Steel Ramp | H24: Food for Team | K24: TBD | L24: Supplier | N24: 15 | O24: =IF(OR(D24="", N24=""), "", ROUND(D24 * N24 / 100, 2)) -> 65.22 | P24: =IF(D24="", "", D24 + O24) -> 500 | Q24: Paid
A25: 45974 | B25: Labour charges of 5 Days | C25: OUT | D25: 2078.26 | E25: Cash | F25: Labour Expense | G25: Fabrication of Steel Ramp | H25: Labour Chares | K25: Mr shahid | L25: Supplier | N25: 15 | O25: =IF(OR(D25="", N25=""), "", ROUND(D25 * N25 / 100, 2)) -> 311.74 | P25: =IF(D25="", "", D25 + O25) -> 2390 | Q25: Paid
A26: 45975 | B26: Petrol for project | C26: OUT | D26: 173.91 | E26: Cash | F26: Fuel Expense | G26: Fabrication of Steel Ramp | H26: Fuel Expense | K26: TBD | L26: Supplier | N26: 15 | O26: =IF(OR(D26="", N26=""), "", ROUND(D26 * N26 / 100, 2)) -> 26.09 | P26: =IF(D26="", "", D26 + O26) -> 200 | Q26: Paid
A27: 45976 | B27: Invoice raised for Fabrication of Steel Ramp | C27: IN | D27: 7425 | E27: Accounts Receivable | F27: Project Income | G27: Fabrication of Steel Ramp | H27: N/A | I27: 1 | K27: Bahri Logistics | L27: Client | M27: INV/2025/00051 | N27: 0 | O27: =IF(OR(D27="", N27=""), "", ROUND(D27 * N27 / 100, 2)) -> 0 | P27: =IF(D27="", "", D27 + O27) -> 7425 | Q27: Credit | R27: 50% final amount is pending
A28: 45976 | B28: Same Invoice raised for Tax Collection | C28: IN | D28: 2227.5 | E28: Accounts Receivable | F28: Project Income | G28: Fabrication of Steel Ramp | H28: N/A | K28: Bahri Logistics | L28: Client | M28: INV/2025/00051 | N28: 0 | O28: =IF(OR(D28="", N28=""), "", ROUND(D28 * N28 / 100, 2)) -> 0 | P28: =IF(D28="", "", D28 + O28) -> 2227.5 | Q28: Credit | R28: 100% VAT amount is pending
A29: 45981 | B29: 100% payment received | C29: IN | D29: 27000 | E29: Cash | F29: Project Income | G29: Fabrication of SS+Steel Pillows | H29: N/A | I29: 10 pcs | K29: Fosam Company Limited | L29: Client | N29: 15 | O29: =IF(OR(D29="", N29=""), "", ROUND(D29 * N29 / 100, 2)) -> 4050 | P29: =IF(D29="", "", D29 + O29) -> 31050 | Q29: Paid | R29: 100% Paymment Received Before starting the Project
A30: 45987 | B30: SIDUR sheet 8mm*1.5m/3m | C30: OUT | D30: 2543.48 | E30: Cash | F30: Material Purchase | G30: Fabrication of SS+Steel Pillows | H30: Material/Tools | K30: Alnafie Steel | L30: Supplier | N30: 15 | O30: =IF(OR(D30="", N30=""), "", ROUND(D30 * N30 / 100, 2)) -> 381.52 | P30: =IF(D30="", "", D30 + O30) -> 2925 | Q30: Paid
A31: 45987 | B31: Lathe Expense | C31: OUT | D31: 1200 | E31: Accounts Payable | F31: Repair & Maintenance Expense | G31: Fabrication of SS+Steel Pillows | H31: Material/Tools | K31: Arif bangali | L31: Supplier | N31: 0 | O31: =IF(OR(D31="", N31=""), "", ROUND(D31 * N31 / 100, 2)) -> 0 | P31: =IF(D31="", "", D31 + O31) -> 1200 | Q31: Credit | R31: Credit Payment for Lathe Work
A32: 45987 | B32: Transport | C32: OUT | D32: 217.39 | E32: Cash | F32: Transport Expense | G32: Fabrication of SS+Steel Pillows | H32: Transport | K32: TBD | L32: Supplier | N32: 15 | O32: =IF(OR(D32="", N32=""), "", ROUND(D32 * N32 / 100, 2)) -> 32.61 | P32: =IF(D32="", "", D32 + O32) -> 250 | Q32: Paid
A33: 45987 | B33: Rolling of SIDUR sheet | C33: OUT | D33: 695.65 | E33: Cash | F33: Material Purchase | G33: Fabrication of SS+Steel Pillows | H33: Material/Tools | K33: MZY Steel | L33: Supplier | N33: 15 | O33: =IF(OR(D33="", N33=""), "", ROUND(D33 * N33 / 100, 2)) -> 104.35 | P33: =IF(D33="", "", D33 + O33) -> 800 | Q33: Paid
A34: 45988 | B34: Welding rods / grinding / paint | C34: OUT | D34: 591.3 | E34: Cash | F34: Equipment Purchase | G34: Fabrication of SS+Steel Pillows | H34: Material/Tools | K34: Baity BTC | L34: Supplier | N34: 15 | O34: =IF(OR(D34="", N34=""), "", ROUND(D34 * N34 / 100, 2)) -> 88.7 | P34: =IF(D34="", "", D34 + O34) -> 680 | Q34: Paid
A35: 45988 | B35: labour charges of 3 days | C35: OUT | D35: 1417.39 | E35: Cash | F35: Labour Expense | G35: Fabrication of SS+Steel Pillows | H35: Material/Tools | K35: Mr shahid | L35: Supplier | N35: 15 | O35: =IF(OR(D35="", N35=""), "", ROUND(D35 * N35 / 100, 2)) -> 212.61 | P35: =IF(D35="", "", D35 + O35) -> 1630 | Q35: Paid
A36: 45988 | B36: Commission | C36: OUT | D36: 4000 | E36: Cash | F36: Commission Paid | G36: Fabrication of SS+Steel Pillows | H36: Commission Paid | K36: fosam agent | L36: Supplier | N36: 0 | O36: =IF(OR(D36="", N36=""), "", ROUND(D36 * N36 / 100, 2)) -> 0 | P36: =IF(D36="", "", D36 + O36) -> 4000 | Q36: Paid | R36: Commission given to Mr Halwani
A37: 45988 | B37: Petrol for project | C37: OUT | D37: 60.87 | E37: Cash | F37: Fuel Expense | G37: Fabrication of SS+Steel Pillows | H37: Fuel Expense | K37: TBD | L37: Supplier | N37: 15 | O37: =IF(OR(D37="", N37=""), "", ROUND(D37 * N37 / 100, 2)) -> 9.13 | P37: =IF(D37="", "", D37 + O37) -> 70 | Q37: Paid
A38: 45988 | B38: Food for team | C38: OUT | D38: 295.65 | E38: Cash | F38: Food Expense | G38: Fabrication of SS+Steel Pillows | H38: Food for Team | K38: TBD | L38: Supplier | N38: 15 | O38: =IF(OR(D38="", N38=""), "", ROUND(D38 * N38 / 100, 2)) -> 44.35 | P38: =IF(D38="", "", D38 + O38) -> 340 | Q38: Paid
A39: 45988 | B39: Steel material | C39: OUT | D39: 434.78 | E39: Cash | F39: Material Purchase | G39: Fabrication of SS+Steel Pillows | H39: Material/Tools | K39: TBD | L39: Supplier | N39: 15 | O39: =IF(OR(D39="", N39=""), "", ROUND(D39 * N39 / 100, 2)) -> 65.22 | P39: =IF(D39="", "", D39 + O39) -> 500 | Q39: Paid
A40: 45989 | B40: Electricity bills paid of work shop+Tariq commission | C40: OUT | D40: 900 | E40: Cash | F40: Electricity Expense | H40: Workshop Electricity bill | K40: Tariq Yamni workshop | L40: Supplier | N40: 0 | O40: =IF(OR(D40="", N40=""), "", ROUND(D40 * N40 / 100, 2)) -> 0 | P40: =IF(D40="", "", D40 + O40) -> 900 | Q40: Paid | R40: Company General Expense
...

Sheet Projects
A1: Project Name | B1: Client Name | C1: Contract Value (Excl. VAT) | D1: VAT 15% | E1: Contract Incl. VAT | F1: Required 50% Advance (Incl. VAT) | G1: Total Income | H1: Total Expense | I1: Net Profit / Loss | J1: Remaining Amount
A2: SS316 Pipeline Work | B2: Oud Lover Factory | C2: 4000 | D2: =IF(C2="","",ROUND(C2*0.15,2)) -> 600 | E2: =IF(C2="","",C2+D2) -> 4600 | F2: =IF(E2="","",E2*0.5) -> 2300 | G2: =IF($A2="","", SUMIFS(Transactions!$P:$P, Transactions!$G:$G,$A2, Transactions!$C:$C,"IN", Transactions!$Q:$Q,"*Paid*")) -> 4600 | H2: =IF($A2="","", SUMIFS(Transactions!$P:$P, Transactions!$G:$G,$A2, Transactions!$C:$C,"OUT")) -> 5499.95 | I2: =IF(C2="","",C2-H2) -> -1499.95 | J2: =IF(E2="","",E2-G2) -> 0
A3: Instalation of Sign Board | B3: Feedco Investment Company | C3: 2000 | D3: =IF(C3="","",ROUND(C3*0.15,2)) -> 300 | E3: =IF(C3="","",C3+D3) -> 2300 | F3: =IF(E3="","",E3*0.5) -> 1150 | G3: =IF($A3="","", SUMIFS(Transactions!$P:$P, Transactions!$G:$G,$A3, Transactions!$C:$C,"IN", Transactions!$Q:$Q,"*Paid*")) -> 2300 | H3: =IF($A3="","", SUMIFS(Transactions!$P:$P, Transactions!$G:$G,$A3, Transactions!$C:$C,"OUT")) -> 890 | I3: =IF(C3="","",C3-H3) -> 1110 | J3: =IF(E3="","",E3-G3) -> 0
A4: Fabrication of Steel Ramp | B4: Bahri Logistics | C4: 14850 | D4: =IF(C4="","",ROUND(C4*0.15,2)) -> 2227.5 | E4: =IF(C4="","",C4+D4) -> 17077.5 | F4: =IF(E4="","",E4*0.5) -> 8538.75 | G4: =IF($A4="","", SUMIFS(Transactions!$P:$P, Transactions!$G:$G,$A4, Transactions!$C:$C,"IN", Transactions!$Q:$Q,"*Paid*")) -> 17077.5 | H4: =IF($A4="","", SUMIFS(Transactions!$P:$P, Transactions!$G:$G,$A4, Transactions!$C:$C,"OUT")) -> 7161.97 | I4: =IF(C4="","",C4-H4) -> 7688.03 | J4: =IF(E4="","",E4-G4) -> 0
A5: Fabrication of SS+Steel Pillows | B5: Fosam Company Limited | C5: 27000 | D5: =IF(C5="","",ROUND(C5*0.15,2)) -> 4050 | E5: =IF(C5="","",C5+D5) -> 31050 | F5: =IF(E5="","",E5*0.5) -> 15525 | G5: =IF($A5="","", SUMIFS(Transactions!$P:$P, Transactions!$G:$G,$A5, Transactions!$C:$C,"IN", Transactions!$Q:$Q,"Paid")) -> 31050 | H5: =IF($A5="","", SUMIFS(Transactions!$P:$P, Transactions!$G:$G,$A5, Transactions!$C:$C,"OUT")) -> 12395 | I5: =IF(C5="","",C5-H5) -> 14605 | J5: =IF(E5="","",E5-G5) -> 0
A6: Fabrication of Steel Shose for Forklift | B6: Bahri Logistics | C6: 4300 | D6: =IF(C6="","",ROUND(C6*0.15,2)) -> 645 | E6: =IF(C6="","",C6+D6) -> 4945 | F6: =IF(E6="","",E6*0.5) -> 2472.5 | G6: =IF($A6="","", SUMIFS(Transactions!$P:$P, Transactions!$G:$G,$A6, Transactions!$C:$C,"IN", Transactions!$Q:$Q,"Paid")) -> 4945 | H6: =IF($A6="","", SUMIFS(Transactions!$P:$P, Transactions!$G:$G,$A6, Transactions!$C:$C,"OUT")) -> 1511.39 | I6: =IF(C6="","",C6-H6) -> 2788.61 | J6: =IF(E6="","",E6-G6) -> 0
A7: Fitting of Press Roller | B7: Feedco Investment Company | C7: 8800 | D7: =IF(C7="","",ROUND(C7*0.15,2)) -> 1320 | E7: =IF(C7="","",C7+D7) -> 10120 | F7: =IF(E7="","",E7*0.5) -> 5060 | G7: =IF($A7="","", SUMIFS(Transactions!$P:$P, Transactions!$G:$G,$A7, Transactions!$C:$C,"IN", Transactions!$Q:$Q,"Paid")) -> 10120 | H7: =IF($A7="","", SUMIFS(Transactions!$P:$P, Transactions!$G:$G,$A7, Transactions!$C:$C,"OUT")) -> 4450 | I7: =IF(C7="","",C7-H7) -> 4350 | J7: =IF(E7="","",E7-G7) -> 0
A8: Epoxy Paint Project Jazzan | B8: Company Rosomat/Wasim | C8: 29900 | D8: =IF(C8="","",ROUND(C8*0.15,2)) -> 4485 | E8: =IF(C8="","",C8+D8) -> 34385 | F8: =IF(E8="","",E8*0.5) -> 17192.5 | G8: =IF($A8="","", SUMIFS(Transactions!$P:$P, Transactions!$G:$G,$A8, Transactions!$C:$C,"IN", Transactions!$Q:$Q,"Paid")) -> 29905 | H8: =IF($A8="","", SUMIFS(Transactions!$P:$P, Transactions!$G:$G,$A8, Transactions!$C:$C,"OUT")) -> 21164.75 | I8: =IF(C8="","",C8-H8) -> 8735.25 | J8: =IF(E8="","",E8-G8) -> 4480
A9: Maintenance of Loader | B9: Sapac Company | C9: 5000 | D9: =IF(C9="","",ROUND(C9*0.15,2)) -> 750 | E9: =IF(C9="","",C9+D9) -> 5750 | F9: =IF(E9="","",E9*0.5) -> 2875 | G9: =IF($A9="","", SUMIFS(Transactions!$P:$P, Transactions!$G:$G,$A9, Transactions!$C:$C,"IN", Transactions!$Q:$Q,"Paid")) -> 5750 | H9: =IF($A9="","", SUMIFS(Transactions!$P:$P, Transactions!$G:$G,$A9, Transactions!$C:$C,"OUT")) -> 2550 | I9: =IF(C9="","",C9-H9) -> 2450 | J9: =IF(E9="","",E9-G9) -> 0
A10: Fabrication of Rollers | B10: Fosam Company Limited | C10: 1700 | D10: =IF(C10="","",ROUND(C10*0.15,2)) -> 255 | E10: =IF(C10="","",C10+D10) -> 1955 | F10: =IF(E10="","",E10*0.5) -> 977.5 | G10: =IF($A10="","", SUMIFS(Transactions!$P:$P, Transactions!$G:$G,$A10, Transactions!$C:$C,"IN", Transactions!$Q:$Q,"Paid")) -> 1955 | H10: =IF($A10="","", SUMIFS(Transactions!$P:$P, Transactions!$G:$G,$A10, Transactions!$C:$C,"OUT")) -> 437 | I10: =IF(C10="","",C10-H10) -> 1263 | J10: =IF(E10="","",E10-G10) -> 0
A11: Fabrication of New Roller/8mm | B11: Prainsa Concrete Company | C11: 14925 | D11: =IF(C11="","",ROUND(C11*0.15,2)) -> 2238.75 | E11: =IF(C11="","",C11+D11) -> 17163.75 | F11: =IF(E11="","",E11*0.5) -> 8581.875 | G11: =IF($A11="","", SUMIFS(Transactions!$P:$P, Transactions!$G:$G,$A11, Transactions!$C:$C,"IN", Transactions!$Q:$Q,"Paid")) -> 17163.75 | H11: =IF($A11="","", SUMIFS(Transactions!$P:$P, Transactions!$G:$G,$A11, Transactions!$C:$C,"OUT")) -> 10577.5 | I11: =IF(C11="","",C11-H11) -> 4347.5 | J11: =IF(E11="","",E11-G11) -> 0
A12: Fabrication stainless steel 304 screw | B12: Feedco Investment Company | C12: 4000 | D12: =IF(C12="","",ROUND(C12*0.15,2)) -> 600 | E12: =IF(C12="","",C12+D12) -> 4600 | F12: =IF(E12="","",E12*0.5) -> 2300 | G12: =IF($A12="","", SUMIFS(Transactions!$P:$P, Transactions!$G:$G,$A12, Transactions!$C:$C,"IN", Transactions!$Q:$Q,"Paid")) -> 4600 | H12: =IF($A12="","", SUMIFS(Transactions!$P:$P, Transactions!$G:$G,$A12, Transactions!$C:$C,"OUT")) -> 2563.49 | I12: =IF(C12="","",C12-H12) -> 1436.51 | J12: =IF(E12="","",E12-G12) -> 0
A13: Modification of aluminum cover | B13: Fosam Company Limited | C13: 750 | D13: =IF(C13="","",ROUND(C13*0.15,2)) -> 112.5 | E13: =IF(C13="","",C13+D13) -> 862.5 | F13: =IF(E13="","",E13*0.5) -> 431.25 | G13: =IF($A13="","", SUMIFS(Transactions!$P:$P, Transactions!$G:$G,$A13, Transactions!$C:$C,"IN", Transactions!$Q:$Q,"Paid")) -> 862.5 | H13: =IF($A13="","", SUMIFS(Transactions!$P:$P, Transactions!$G:$G,$A13, Transactions!$C:$C,"OUT")) -> 345 | I13: =IF(C13="","",C13-H13) -> 405 | J13: =IF(E13="","",E13-G13) -> 0
A14: Maintenance of Track Adjuster Cylinder | B14: Gems Reviva Company | C14: 3600 | D14: =IF(C14="","",ROUND(C14*0.15,2)) -> 540 | E14: =IF(C14="","",C14+D14) -> 4140 | F14: =IF(E14="","",E14*0.5) -> 2070 | G14: =IF($A14="","", SUMIFS(Transactions!$P:$P, Transactions!$G:$G,$A14, Transactions!$C:$C,"IN", Transactions!$Q:$Q,"Paid")) -> 0 | H14: =IF($A14="","", SUMIFS(Transactions!$P:$P, Transactions!$G:$G,$A14, Transactions!$C:$C,"OUT")) -> 1178.7 | I14: =IF(C14="","",C14-H14) -> 2421.3 | J14: =IF(E14="","",E14-G14) -> 4140
A15: Maintenance of Rotary Lobe Blower | B15: Gems Reviva Company | C15: 8500 | D15: =IF(C15="","",ROUND(C15*0.15,2)) -> 1275 | E15: =IF(C15="","",C15+D15) -> 9775 | F15: =IF(E15="","",E15*0.5) -> 4887.5 | G15: =IF($A15="","", SUMIFS(Transactions!$P:$P, Transactions!$G:$G,$A15, Transactions!$C:$C,"IN", Transactions!$Q:$Q,"Paid")) -> 0 | H15: =IF($A15="","", SUMIFS(Transactions!$P:$P, Transactions!$G:$G,$A15, Transactions!$C:$C,"OUT")) -> 4846.45 | I15: =IF(C15="","",C15-H15) -> 3653.55 | J15: =IF(E15="","",E15-G15) -> 9775
A16: Supply of Water Sensor | B16: Modern Building Leaders | C16: 5000 | D16: =IF(C16="","",ROUND(C16*0.15,2)) -> 750 | E16: =IF(C16="","",C16+D16) -> 5750 | F16: =IF(E16="","",E16*0.5) -> 2875 | G16: =IF($A16="","", SUMIFS(Transactions!$P:$P, Transactions!$G:$G,$A16, Transactions!$C:$C,"IN", Transactions!$Q:$Q,"Paid")) -> 5750 | H16: =IF($A16="","", SUMIFS(Transactions!$P:$P, Transactions!$G:$G,$A16, Transactions!$C:$C,"OUT")) -> 0 | I16: =IF(C16="","",C16-H16) -> 5000 | J16: =IF(E16="","",E16-G16) -> 0
... A29: Fabrication of Doors/15mm 2pc | B29: Feedco Investment Company | C29: 13540 | D29: =IF(C29="","",ROUND(C29*0.15,2)) -> 2031 | E29: =IF(C29="","",C29+D29) -> 15571 | F29: =IF(E29="","",E29*0.5) -> 7785.5 | G29: =IF($A29="","", SUMIFS(Transactions!$P:$P, Transactions!$G:$G,$A29, Transactions!$C:$C,"IN", Transactions!$Q:$Q,"Paid")) -> 15569.85 | H29: =IF($A29="","", SUMIFS(Transactions!$P:$P, Transactions!$G:$G,$A29, Transactions!$C:$C,"OUT")) -> 7122.87 | I29: =IF(C29="","",C29-H29) -> 6417.13 | J29: =IF(E29="","",E29-G29) -> 1.15
A30: PO-0155+PO-0156 (ClipBoard+wood Aternator) | B30: Al-Markaz company | C30: 23080 | D30: =IF(C30="","",ROUND(C30*0.15,2)) -> 3462 | E30: =IF(C30="","",C30+D30) -> 26542 | F30: =IF(E30="","",E30*0.5) -> 13271 | G30: =IF($A30="","", SUMIFS(Transactions!$P:$P, Transactions!$G:$G,$A30, Transactions!$C:$C,"IN", Transactions!$Q:$Q,"Paid")) -> 35769.6 | H30: =IF($A30="","", SUMIFS(Transactions!$P:$P, Transactions!$G:$G,$A30, Transactions!$C:$C,"OUT")) -> 27300.75 | I30: =IF(C30="","",C30-H30) -> -4220.75 | J30: =IF(E30="","",E30-G30) -> -9227.6 | K30: Amount of Two invoices
A31: Maintenance of Bole Drum | B31: Emar Ayan Industrial Factory | C31: 8800 | D31: =IF(C31="","",ROUND(C31*0.15,2)) -> 1320 | E31: =IF(C31="","",C31+D31) -> 10120 | F31: =IF(E31="","",E31*0.5) -> 5060 | G31: =IF($A31="","", SUMIFS(Transactions!$P:$P, Transactions!$G:$G,$A31, Transactions!$C:$C,"IN", Transactions!$Q:$Q,"Paid")) -> 5060 | H31: =IF($A31="","", SUMIFS(Transactions!$P:$P, Transactions!$G:$G,$A31, Transactions!$C:$C,"OUT")) -> 350 | I31: =IF(C31="","",C31-H31) -> 8450 | J31: =IF(E31="","",E31-G31) -> 5060
D32: =IF(C32="","",ROUND(C32*0.15,2)) | E32: =IF(C32="","",C32+D32) | F32: =IF(E32="","",E32*0.5) | G32: =IF($A32="","", SUMIFS(Transactions!$P:$P, Transactions!$G:$G,$A32, Transactions!$C:$C,"IN", Transactions!$Q:$Q,"Paid")) | H32: =IF($A32="","", SUMIFS(Transactions!$P:$P, Transactions!$G:$G,$A32, Transactions!$C:$C,"OUT")) | I32: =IF(C32="","",C32-H32) | J32: =IF(E32="","",E32-G32)
D33: =IF(C33="","",ROUND(C33*0.15,2)) | E33: =IF(C33="","",C33+D33) | F33: =IF(E33="","",E33*0.5) | G33: =IF($A33="","", SUMIFS(Transactions!$P:$P, Transactions!$G:$G,$A33, Transactions!$C:$C,"IN", Transactions!$Q:$Q,"Paid")) | H33: =IF($A33="","", SUMIFS(Transactions!$P:$P, Transactions!$G:$G,$A33, Transactions!$C:$C,"OUT")) | I33: =IF(C33="","",C33-H33) | J33: =IF(E33="","",E33-G33)
D34: =IF(C34="","",ROUND(C34*0.15,2)) | E34: =IF(C34="","",C34+D34) | F34: =IF(E34="","",E34*0.5) | G34: =IF($A34="","", SUMIFS(Transactions!$P:$P, Transactions!$G:$G,$A34, Transactions!$C:$C,"IN", Transactions!$Q:$Q,"Paid")) | H34: =IF($A34="","", SUMIFS(Transactions!$P:$P, Transactions!$G:$G,$A34, Transactions!$C:$C,"OUT")) | I34: =IF(C34="","",C34-H34) | J34: =IF(E34="","",E34-G34)
D35: =IF(C35="","",ROUND(C35*0.15,2)) | E35: =IF(C35="","",C35+D35) | F35: =IF(E35="","",E35*0.5) | G35: =IF($A35="","", SUMIFS(Transactions!$P:$P, Transactions!$G:$G,$A35, Transactions!$C:$C,"IN", Transactions!$Q:$Q,"Paid")) | H35: =IF($A35="","", SUMIFS(Transactions!$P:$P, Transactions!$G:$G,$A35, Transactions!$C:$C,"OUT")) | I35: =IF(C35="","",C35-H35) | J35: =IF(E35="","",E35-G35)
D36: =IF(C36="","",ROUND(C36*0.15,2)) | E36: =IF(C36="","",C36+D36) | F36: =IF(E36="","",E36*0.5) | G36: =IF($A36="","", SUMIFS(Transactions!$P:$P, Transactions!$G:$G,$A36, Transactions!$C:$C,"IN", Transactions!$Q:$Q,"Paid")) | H36: =IF($A36="","", SUMIFS(Transactions!$P:$P, Transactions!$G:$G,$A36, Transactions!$C:$C,"OUT")) | I36: =IF(C36="","",C36-H36) | J36: =IF(E36="","",E36-G36)
D37: =IF(C37="","",ROUND(C37*0.15,2)) | E37: =IF(C37="","",C37+D37) | F37: =IF(E37="","",E37*0.5) | G37: =IF($A37="","", SUMIFS(Transactions!$P:$P, Transactions!$G:$G,$A37, Transactions!$C:$C,"IN", Transactions!$Q:$Q,"Paid")) | H37: =IF($A37="","", SUMIFS(Transactions!$P:$P, Transactions!$G:$G,$A37, Transactions!$C:$C,"OUT")) | I37: =IF(C37="","",C37-H37) | J37: =IF(E37="","",E37-G37)
D38: =IF(C38="","",ROUND(C38*0.15,2)) | E38: =IF(C38="","",C38+D38) | F38: =IF(E38="","",E38*0.5) | G38: =IF($A38="","", SUMIFS(Transactions!$P:$P, Transactions!$G:$G,$A38, Transactions!$C:$C,"IN", Transactions!$Q:$Q,"Paid")) | H38: =IF($A38="","", SUMIFS(Transactions!$P:$P, Transactions!$G:$G,$A38, Transactions!$C:$C,"OUT")) | I38: =IF(C38="","",C38-H38) | J38: =IF(E38="","",E38-G38)
D39: =IF(C39="","",ROUND(C39*0.15,2)) | E39: =IF(C39="","",C39+D39) | F39: =IF(E39="","",E39*0.5) | G39: =IF($A39="","", SUMIFS(Transactions!$P:$P, Transactions!$G:$G,$A39, Transactions!$C:$C,"IN", Transactions!$Q:$Q,"Paid")) | H39: =IF($A39="","", SUMIFS(Transactions!$P:$P, Transactions!$G:$G,$A39, Transactions!$C:$C,"OUT")) | I39: =IF(C39="","",C39-H39) | J39: =IF(E39="","",E39-G39)
D40: =IF(C40="","",ROUND(C40*0.15,2)) | E40: =IF(C40="","",C40+D40) | F40: =IF(E40="","",E40*0.5) | G40: =IF($A40="","", SUMIFS(Transactions!$P:$P, Transactions!$G:$G,$A40, Transactions!$C:$C,"IN", Transactions!$Q:$Q,"Paid")) | H40: =IF($A40="","", SUMIFS(Transactions!$P:$P, Transactions!$G:$G,$A40, Transactions!$C:$C,"OUT")) | I40: =IF(C40="","",C40-H40) | J40: =IF(E40="","",E40-G40)
D41: =IF(C41="","",ROUND(C41*0.15,2)) | E41: =IF(C41="","",C41+D41) | F41: =IF(E41="","",E41*0.5) | G41: =IF($A41="","", SUMIFS(Transactions!$P:$P, Transactions!$G:$G,$A41, Transactions!$C:$C,"IN", Transactions!$Q:$Q,"Paid")) | H41: =IF($A41="","", SUMIFS(Transactions!$P:$P, Transactions!$G:$G,$A41, Transactions!$C:$C,"OUT")) | I41: =IF(C41="","",C41-H41) | J41: =IF(E41="","",E41-G41)
D42: =IF(C42="","",ROUND(C42*0.15,2)) | E42: =IF(C42="","",C42+D42) | F42: =IF(E42="","",E42*0.5) | G42: =IF($A42="","", SUMIFS(Transactions!$P:$P, Transactions!$G:$G,$A42, Transactions!$C:$C,"IN", Transactions!$Q:$Q,"Paid")) | H42: =IF($A42="","", SUMIFS(Transactions!$P:$P, Transactions!$G:$G,$A42, Transactions!$C:$C,"OUT")) | I42: =IF(C42="","",C42-H42) | J42: =IF(E42="","",E42-G42)
D43: =IF(C43="","",ROUND(C43*0.15,2)) | E43: =IF(C43="","",C43+D43) | F43: =IF(E43="","",E43*0.5) | G43: =IF($A43="","", SUMIFS(Transactions!$P:$P, Transactions!$G:$G,$A43, Transactions!$C:$C,"IN", Transactions!$Q:$Q,"Paid")) | H43: =IF($A43="","", SUMIFS(Transactions!$P:$P, Transactions!$G:$G,$A43, Transactions!$C:$C,"OUT")) | I43: =IF(C43="","",C43-H43) | J43: =IF(E43="","",E43-G43)
... D2000: =IF(C2000="","",ROUND(C2000*0.15,2)) | E2000: =IF(C2000="","",C2000+D2000) | F2000: =IF(E2000="","",E2000*0.5) | G2000: =IF($A2000="","", SUMIFS(Transactions!$P:$P, Transactions!$G:$G,$A2000, Transactions!$C:$C,"IN", Transactions!$Q:$Q,"Paid")) | H2000: =IF($A2000="","", SUMIFS(Transactions!$P:$P, Transactions!$G:$G,$A2000, Transactions!$C:$C,"OUT")) | I2000: =IF(C2000="","",C2000-H2000) | J2000: =IF(E2000="","",E2000-G2000)

Sheet Accounts_Summary
A1: Account Name | B1: Total IN | C1: Total OUT | D1: Balance
A2: Cash | B2: =SUMIFS(Transactions!$P:$P,Transactions!$C:$C,"IN",Transactions!$E:$E,$A2) -> 418456.21 | C2: =SUMIFS(Transactions!$P:$P,Transactions!$C:$C,"OUT",Transactions!$E:$E,$A2) -> 434675.71 | D2: =B2-C2 -> -16219.5 | E2: With VAT
A3: Bank | B3: =SUMIFS(Transactions!$P:$P,Transactions!$C:$C,"IN",Transactions!$E:$E,$A3) -> 0 | C3: =SUMIFS(Transactions!$P:$P,Transactions!$C:$C,"OUT",Transactions!$E:$E,$A3) -> 0 | D3: =B3-C3 -> 0 | E3: With VAT
A4: Owner Contribution | B4: =SUMIFS(Transactions!$P:$P,Transactions!$C:$C,"IN",Transactions!$E:$E,$A4) -> 0 | C4: =SUMIFS(Transactions!$P:$P,Transactions!$C:$C,"OUT",Transactions!$E:$E,$A4) -> 0 | D4: =B4-C4 -> 0 | E4: Without VAT Amount
A5: Owner Drawings | B5: =SUMIFS(Transactions!$D:$D, Transactions!$F:$F, "Owner Drawings", Transactions!$C:$C, "IN") -> 0 | C5: =SUMIFS(Transactions!$D:$D, Transactions!$F:$F, "Owner Drawings", Transactions!$C:$C, "OUT") -> 35145 | D5: =B5 - C5 -> -35145 | E5: Without VAT Amount
A6: Accounts Receivable | B6: =SUMIFS(Transactions!$D:$D, Transactions!$E:$E, "Accounts Receivable", Transactions!$C:$C, "IN") -> 30052.5 | C6: =SUMIFS(Transactions!$D:$D, Transactions!$E:$E, "Accounts Receivable", Transactions!$C:$C, "OUT") -> 17952.5 | D6: =B6 - C6 -> 12100 | E6: Without VAT Amount
A7: Accounts Payable | B7: =SUMIFS(Transactions!$D:$D, Transactions!$E:$E, "Accounts Payable", Transactions!$C:$C, "IN") -> 3134.79 | C7: =SUMIFS(Transactions!$D:$D, Transactions!$E:$E, "Accounts Payable", Transactions!$C:$C, "OUT") -> 8734.79 | D7: =B7-C7 -> -5600 | E7: Without VAT Amount
A8: Employee Payable | B8: =SUMIFS(Transactions!$D:$D, Transactions!$E:$E, "Employee Payable", Transactions!$C:$C, "IN") -> 0 | C8: =SUMIFS(Transactions!$D:$D, Transactions!$E:$E, "Employee Payable", Transactions!$C:$C, "OUT") -> 0 | D8: =B8 - C8 -> 0 | E8: Without VAT Amount
A9: Employee Advance | B9: =SUMIFS(Transactions!$D:$D, Transactions!$E:$E, "Employee Advance", Transactions!$C:$C, "IN") -> 0 | C9: =SUMIFS(Transactions!$D:$D, Transactions!$E:$E, "Employee Advance", Transactions!$C:$C, "OUT") -> 17486 | D9: =B9-C9 -> -17486 | E9: Without VAT Amount

Sheet Tax Report
A1: Month | B1: Year | C1: Total Sales (Excl. VAT) | D1: Output VAT 15% | E1: Total Purchases (Excl. VAT) | F1: Input VAT 15% | G1: Net VAT Payable
A2: 11 | B2: 2025 | C2: =IF(OR($A2="",$B2=""),"", SUMIFS(Transactions!$D:$D, Transactions!$C:$C,"IN", Transactions!$L:$L,"Client", Transactions!$Q:$Q,"*Paid*", Transactions!$A:$A,">="&DATE($B2,$A2,1), Transactions!$A:$A,"<"&EDATE(DATE($B2,$A2,1),1) ) ) -> 40425 | D2: =IF(OR($A2="",$B2=""),"", SUMIFS(Transactions!$O:$O, Transactions!$C:$C,"IN", Transactions!$L:$L,"Client", Transactions!$Q:$Q,"*Paid*", Transactions!$A:$A,">="&DATE($B2,$A2,1), Transactions!$A:$A,"<"&EDATE(DATE($B2,$A2,1),1) ) ) -> 4950 | E2: =SUMIFS( Transactions!$D:$D, Transactions!$C:$C,"OUT", Transactions!$E:$E,"Cash", Transactions!$A:$A,">=" & DATE($B2,$A2,1), Transactions!$A:$A,"<" & DATE($B2,$A2+1,1) ) -> 30410.05 | F2: =SUMIFS( Transactions!$O:$O, Transactions!$C:$C,"OUT", Transactions!$E:$E,"Cash", Transactions!$A:$A,">=" & DATE($B2,$A2,1), Transactions!$A:$A,"<" & DATE($B2,$A2+1,1) ) -> 2824.11 | G2: =IF(OR(D2="",F2=""),"",D2-F2) -> 2125.89
A3: 12 | B3: 2025 | C3: =IF(OR($A3="",$B3=""),"", SUMIFS(Transactions!$D:$D, Transactions!$C:$C,"IN", Transactions!$L:$L,"Client", Transactions!$Q:$Q,"*Paid*", Transactions!$A:$A,">="&DATE($B3,$A3,1), Transactions!$A:$A,"<"&EDATE(DATE($B3,$A3,1),1) ) ) -> 67827.5 | D3: =IF(OR($A3="",$B3=""),"", SUMIFS(Transactions!$O:$O, Transactions!$C:$C,"IN", Transactions!$L:$L,"Client", Transactions!$Q:$Q,"*Paid*", Transactions!$A:$A,">="&DATE($B3,$A3,1), Transactions!$A:$A,"<"&EDATE(DATE($B3,$A3,1),1) ) ) -> 6476.25 | E3: =SUMIFS( Transactions!$D:$D, Transactions!$C:$C,"OUT", Transactions!$E:$E,"Cash", Transactions!$A:$A,">=" & DATE($B3,$A3,1), Transactions!$A:$A,"<" & DATE($B3,$A3+1,1) ) -> 76881.28 | F3: =SUMIFS( Transactions!$O:$O, Transactions!$C:$C,"OUT", Transactions!$E:$E,"Cash", Transactions!$A:$A,">=" & DATE($B3,$A3,1), Transactions!$A:$A,"<" & DATE($B3,$A3+1,1) ) -> 3566.25 | G3: =IF(OR(D3="",F3=""),"",D3-F3) -> 2910
A4: 1 | B4: 2026 | C4: =IF(OR($A4="",$B4=""),"", SUMIFS(Transactions!$D:$D, Transactions!$C:$C,"IN", Transactions!$L:$L,"Client", Transactions!$Q:$Q,"*Paid*", Transactions!$A:$A,">="&DATE($B4,$A4,1), Transactions!$A:$A,"<"&EDATE(DATE($B4,$A4,1),1) ) ) -> 63389.57 | D4: =IF(OR($A4="",$B4=""),"", SUMIFS(Transactions!$O:$O, Transactions!$C:$C,"IN", Transactions!$L:$L,"Client", Transactions!$Q:$Q,"*Paid*", Transactions!$A:$A,">="&DATE($B4,$A4,1), Transactions!$A:$A,"<"&EDATE(DATE($B4,$A4,1),1) ) ) -> 9283.44 | E4: =SUMIFS( Transactions!$D:$D, Transactions!$C:$C,"OUT", Transactions!$E:$E,"Cash", Transactions!$A:$A,">=" & DATE($B4,$A4,1), Transactions!$A:$A,"<" & DATE($B4,$A4+1,1) ) -> 57420.58 | F4: =SUMIFS( Transactions!$O:$O, Transactions!$C:$C,"OUT", Transactions!$E:$E,"Cash", Transactions!$A:$A,">=" & DATE($B4,$A4,1), Transactions!$A:$A,"<" & DATE($B4,$A4+1,1) ) -> 1507.89 | G4: =IF(OR(D4="",F4=""),"",D4-F4) -> 7775.55
A5: 2 | B5: 2026 | C5: =IF(OR($A5="",$B5=""),"", SUMIFS(Transactions!$D:$D, Transactions!$C:$C,"IN", Transactions!$L:$L,"Client", Transactions!$Q:$Q,"*Paid*", Transactions!$A:$A,">="&DATE($B5,$A5,1), Transactions!$A:$A,"<"&EDATE(DATE($B5,$A5,1),1) ) ) -> 115500 | D5: =IF(OR($A5="",$B5=""),"", SUMIFS(Transactions!$O:$O, Transactions!$C:$C,"IN", Transactions!$L:$L,"Client", Transactions!$Q:$Q,"*Paid*", Transactions!$A:$A,">="&DATE($B5,$A5,1), Transactions!$A:$A,"<"&EDATE(DATE($B5,$A5,1),1) ) ) -> 17325 | E5: =SUMIFS( Transactions!$D:$D, Transactions!$C:$C,"OUT", Transactions!$E:$E,"Cash", Transactions!$A:$A,">=" & DATE($B5,$A5,1), Transactions!$A:$A,"<" & DATE($B5,$A5+1,1) ) -> 114889.18 | F5: =SUMIFS( Transactions!$O:$O, Transactions!$C:$C,"OUT", Transactions!$E:$E,"Cash", Transactions!$A:$A,">=" & DATE($B5,$A5,1), Transactions!$A:$A,"<" & DATE($B5,$A5+1,1) ) -> 3434.54 | G5: =IF(OR(D5="",F5=""),"",D5-F5) -> 13890.46
A6: 3 | B6: 2026 | C6: =IF(OR($A6="",$B6=""),"", SUMIFS(Transactions!$D:$D, Transactions!$C:$C,"IN", Transactions!$L:$L,"Client", Transactions!$Q:$Q,"*Paid*", Transactions!$A:$A,">="&DATE($B6,$A6,1), Transactions!$A:$A,"<"&EDATE(DATE($B6,$A6,1),1) ) ) -> 83448 | D6: =IF(OR($A6="",$B6=""),"", SUMIFS(Transactions!$O:$O, Transactions!$C:$C,"IN", Transactions!$L:$L,"Client", Transactions!$Q:$Q,"*Paid*", Transactions!$A:$A,">="&DATE($B6,$A6,1), Transactions!$A:$A,"<"&EDATE(DATE($B6,$A6,1),1) ) ) -> 9831.45 | E6: =SUMIFS( Transactions!$D:$D, Transactions!$C:$C,"OUT", Transactions!$E:$E,"Cash", Transactions!$A:$A,">=" & DATE($B6,$A6,1), Transactions!$A:$A,"<" & DATE($B6,$A6+1,1) ) -> 129469.78 | F6: =SUMIFS( Transactions!$O:$O, Transactions!$C:$C,"OUT", Transactions!$E:$E,"Cash", Transactions!$A:$A,">=" & DATE($B6,$A6,1), Transactions!$A:$A,"<" & DATE($B6,$A6+1,1) ) -> 4892.25 | G6: =IF(OR(D6="",F6=""),"",D6-F6) -> 4939.2
C7: =IF(OR($A7="",$B7=""),"", SUMIFS(Transactions!$D:$D, Transactions!$C:$C,"IN", Transactions!$L:$L,"Client", Transactions!$Q:$Q,"*Paid*", Transactions!$A:$A,">="&DATE($B7,$A7,1), Transactions!$A:$A,"<"&EDATE(DATE($B7,$A7,1),1) ) ) | D7: =IF(OR($A7="",$B7=""),"", SUMIFS(Transactions!$O:$O, Transactions!$C:$C,"IN", Transactions!$L:$L,"Client", Transactions!$Q:$Q,"*Paid*", Transactions!$A:$A,">="&DATE($B7,$A7,1), Transactions!$A:$A,"<"&EDATE(DATE($B7,$A7,1),1) ) ) | E7: =SUMIFS( Transactions!$D:$D, Transactions!$C:$C,"OUT", Transactions!$E:$E,"Cash", Transactions!$A:$A,">=" & DATE($B7,$A7,1), Transactions!$A:$A,"<" & DATE($B7,$A7+1,1) ) -> 0 | F7: =SUMIFS( Transactions!$O:$O, Transactions!$C:$C,"OUT", Transactions!$E:$E,"Cash", Transactions!$A:$A,">=" & DATE($B7,$A7,1), Transactions!$A:$A,"<" & DATE($B7,$A7+1,1) ) -> 0 | G7: =IF(OR(D7="",F7=""),"",D7-F7)
C8: =IF(OR($A8="",$B8=""),"", SUMIFS(Transactions!$D:$D, Transactions!$C:$C,"IN", Transactions!$L:$L,"Client", Transactions!$Q:$Q,"*Paid*", Transactions!$A:$A,">="&DATE($B8,$A8,1), Transactions!$A:$A,"<"&EDATE(DATE($B8,$A8,1),1) ) ) | D8: =IF(OR($A8="",$B8=""),"", SUMIFS(Transactions!$O:$O, Transactions!$C:$C,"IN", Transactions!$L:$L,"Client", Transactions!$Q:$Q,"*Paid*", Transactions!$A:$A,">="&DATE($B8,$A8,1), Transactions!$A:$A,"<"&EDATE(DATE($B8,$A8,1),1) ) ) | E8: =SUMIFS( Transactions!$D:$D, Transactions!$C:$C,"OUT", Transactions!$E:$E,"Cash", Transactions!$A:$A,">=" & DATE($B8,$A8,1), Transactions!$A:$A,"<" & DATE($B8,$A8+1,1) ) -> 0 | F8: =SUMIFS( Transactions!$O:$O, Transactions!$C:$C,"OUT", Transactions!$E:$E,"Cash", Transactions!$A:$A,">=" & DATE($B8,$A8,1), Transactions!$A:$A,"<" & DATE($B8,$A8+1,1) ) -> 0 | G8: =IF(OR(D8="",F8=""),"",D8-F8)
C9: =IF(OR($A9="",$B9=""),"", SUMIFS(Transactions!$D:$D, Transactions!$C:$C,"IN", Transactions!$L:$L,"Client", Transactions!$Q:$Q,"*Paid*", Transactions!$A:$A,">="&DATE($B9,$A9,1), Transactions!$A:$A,"<"&EDATE(DATE($B9,$A9,1),1) ) ) | D9: =IF(OR($A9="",$B9=""),"", SUMIFS(Transactions!$O:$O, Transactions!$C:$C,"IN", Transactions!$L:$L,"Client", Transactions!$Q:$Q,"*Paid*", Transactions!$A:$A,">="&DATE($B9,$A9,1), Transactions!$A:$A,"<"&EDATE(DATE($B9,$A9,1),1) ) ) | E9: =SUMIFS( Transactions!$D:$D, Transactions!$C:$C,"OUT", Transactions!$E:$E,"Cash", Transactions!$A:$A,">=" & DATE($B9,$A9,1), Transactions!$A:$A,"<" & DATE($B9,$A9+1,1) ) -> 0 | F9: =SUMIFS( Transactions!$O:$O, Transactions!$C:$C,"OUT", Transactions!$E:$E,"Cash", Transactions!$A:$A,">=" & DATE($B9,$A9,1), Transactions!$A:$A,"<" & DATE($B9,$A9+1,1) ) -> 0 | G9: =IF(OR(D9="",F9=""),"",D9-F9)
C10: =IF(OR($A10="",$B10=""),"", SUMIFS(Transactions!$D:$D, Transactions!$C:$C,"IN", Transactions!$L:$L,"Client", Transactions!$Q:$Q,"*Paid*", Transactions!$A:$A,">="&DATE($B10,$A10,1), Transactions!$A:$A,"<"&EDATE(DATE($B10,$A10,1),1) ) ) | D10: =IF(OR($A10="",$B10=""),"", SUMIFS(Transactions!$O:$O, Transactions!$C:$C,"IN", Transactions!$L:$L,"Client", Transactions!$Q:$Q,"*Paid*", Transactions!$A:$A,">="&DATE($B10,$A10,1), Transactions!$A:$A,"<"&EDATE(DATE($B10,$A10,1),1) ) ) | E10: =SUMIFS( Transactions!$D:$D, Transactions!$C:$C,"OUT", Transactions!$E:$E,"Cash", Transactions!$A:$A,">=" & DATE($B10,$A10,1), Transactions!$A:$A,"<" & DATE($B10,$A10+1,1) ) -> 0 | F10: =SUMIFS( Transactions!$O:$O, Transactions!$C:$C,"OUT", Transactions!$E:$E,"Cash", Transactions!$A:$A,">=" & DATE($B10,$A10,1), Transactions!$A:$A,"<" & DATE($B10,$A10+1,1) ) -> 0 | G10: =IF(OR(D10="",F10=""),"",D10-F10)
C11: =IF(OR($A11="",$B11=""),"", SUMIFS(Transactions!$D:$D, Transactions!$C:$C,"IN", Transactions!$L:$L,"Client", Transactions!$Q:$Q,"*Paid*", Transactions!$A:$A,">="&DATE($B11,$A11,1), Transactions!$A:$A,"<"&EDATE(DATE($B11,$A11,1),1) ) ) | D11: =IF(OR($A11="",$B11=""),"", SUMIFS(Transactions!$O:$O, Transactions!$C:$C,"IN", Transactions!$L:$L,"Client", Transactions!$Q:$Q,"*Paid*", Transactions!$A:$A,">="&DATE($B11,$A11,1), Transactions!$A:$A,"<"&EDATE(DATE($B11,$A11,1),1) ) ) | E11: =SUMIFS( Transactions!$D:$D, Transactions!$C:$C,"OUT", Transactions!$E:$E,"Cash", Transactions!$A:$A,">=" & DATE($B11,$A11,1), Transactions!$A:$A,"<" & DATE($B11,$A11+1,1) ) -> 0 | F11: =SUMIFS( Transactions!$O:$O, Transactions!$C:$C,"OUT", Transactions!$E:$E,"Cash", Transactions!$A:$A,">=" & DATE($B11,$A11,1), Transactions!$A:$A,"<" & DATE($B11,$A11+1,1) ) -> 0 | G11: =IF(OR(D11="",F11=""),"",D11-F11)
C12: =IF(OR($A12="",$B12=""),"", SUMIFS(Transactions!$D:$D, Transactions!$C:$C,"IN", Transactions!$L:$L,"Client", Transactions!$Q:$Q,"*Paid*", Transactions!$A:$A,">="&DATE($B12,$A12,1), Transactions!$A:$A,"<"&EDATE(DATE($B12,$A12,1),1) ) ) | D12: =IF(OR($A12="",$B12=""),"", SUMIFS(Transactions!$O:$O, Transactions!$C:$C,"IN", Transactions!$L:$L,"Client", Transactions!$Q:$Q,"*Paid*", Transactions!$A:$A,">="&DATE($B12,$A12,1), Transactions!$A:$A,"<"&EDATE(DATE($B12,$A12,1),1) ) ) | E12: =SUMIFS( Transactions!$D:$D, Transactions!$C:$C,"OUT", Transactions!$E:$E,"Cash", Transactions!$A:$A,">=" & DATE($B12,$A12,1), Transactions!$A:$A,"<" & DATE($B12,$A12+1,1) ) -> 0 | F12: =SUMIFS( Transactions!$O:$O, Transactions!$C:$C,"OUT", Transactions!$E:$E,"Cash", Transactions!$A:$A,">=" & DATE($B12,$A12,1), Transactions!$A:$A,"<" & DATE($B12,$A12+1,1) ) -> 0 | G12: =IF(OR(D12="",F12=""),"",D12-F12)
C13: =IF(OR($A13="",$B13=""),"", SUMIFS(Transactions!$D:$D, Transactions!$C:$C,"IN", Transactions!$L:$L,"Client", Transactions!$Q:$Q,"*Paid*", Transactions!$A:$A,">="&DATE($B13,$A13,1), Transactions!$A:$A,"<"&EDATE(DATE($B13,$A13,1),1) ) ) | D13: =IF(OR($A13="",$B13=""),"", SUMIFS(Transactions!$O:$O, Transactions!$C:$C,"IN", Transactions!$L:$L,"Client", Transactions!$Q:$Q,"*Paid*", Transactions!$A:$A,">="&DATE($B13,$A13,1), Transactions!$A:$A,"<"&EDATE(DATE($B13,$A13,1),1) ) ) | E13: =SUMIFS( Transactions!$D:$D, Transactions!$C:$C,"OUT", Transactions!$E:$E,"Cash", Transactions!$A:$A,">=" & DATE($B13,$A13,1), Transactions!$A:$A,"<" & DATE($B13,$A13+1,1) ) -> 0 | F13: =SUMIFS( Transactions!$O:$O, Transactions!$C:$C,"OUT", Transactions!$E:$E,"Cash", Transactions!$A:$A,">=" & DATE($B13,$A13,1), Transactions!$A:$A,"<" & DATE($B13,$A13+1,1) ) -> 0 | G13: =IF(OR(D13="",F13=""),"",D13-F13)
C14: =IF(OR($A14="",$B14=""),"", SUMIFS(Transactions!$D:$D, Transactions!$C:$C,"IN", Transactions!$L:$L,"Client", Transactions!$Q:$Q,"*Paid*", Transactions!$A:$A,">="&DATE($B14,$A14,1), Transactions!$A:$A,"<"&EDATE(DATE($B14,$A14,1),1) ) ) | D14: =IF(OR($A14="",$B14=""),"", SUMIFS(Transactions!$O:$O, Transactions!$C:$C,"IN", Transactions!$L:$L,"Client", Transactions!$Q:$Q,"*Paid*", Transactions!$A:$A,">="&DATE($B14,$A14,1), Transactions!$A:$A,"<"&EDATE(DATE($B14,$A14,1),1) ) ) | E14: =SUMIFS( Transactions!$D:$D, Transactions!$C:$C,"OUT", Transactions!$E:$E,"Cash", Transactions!$A:$A,">=" & DATE($B14,$A14,1), Transactions!$A:$A,"<" & DATE($B14,$A14+1,1) ) -> 0 | F14: =SUMIFS( Transactions!$O:$O, Transactions!$C:$C,"OUT", Transactions!$E:$E,"Cash", Transactions!$A:$A,">=" & DATE($B14,$A14,1), Transactions!$A:$A,"<" & DATE($B14,$A14+1,1) ) -> 0 | G14: =IF(OR(D14="",F14=""),"",D14-F14)
C15: =IF(OR($A15="",$B15=""),"", SUMIFS(Transactions!$D:$D, Transactions!$C:$C,"IN", Transactions!$L:$L,"Client", Transactions!$Q:$Q,"*Paid*", Transactions!$A:$A,">="&DATE($B15,$A15,1), Transactions!$A:$A,"<"&EDATE(DATE($B15,$A15,1),1) ) ) | D15: =IF(OR($A15="",$B15=""),"", SUMIFS(Transactions!$O:$O, Transactions!$C:$C,"IN", Transactions!$L:$L,"Client", Transactions!$Q:$Q,"*Paid*", Transactions!$A:$A,">="&DATE($B15,$A15,1), Transactions!$A:$A,"<"&EDATE(DATE($B15,$A15,1),1) ) ) | E15: =SUMIFS( Transactions!$D:$D, Transactions!$C:$C,"OUT", Transactions!$E:$E,"Cash", Transactions!$A:$A,">=" & DATE($B15,$A15,1), Transactions!$A:$A,"<" & DATE($B15,$A15+1,1) ) -> 0 | F15: =SUMIFS( Transactions!$O:$O, Transactions!$C:$C,"OUT", Transactions!$E:$E,"Cash", Transactions!$A:$A,">=" & DATE($B15,$A15,1), Transactions!$A:$A,"<" & DATE($B15,$A15+1,1) ) -> 0 | G15: =IF(OR(D15="",F15=""),"",D15-F15)
C16: =IF(OR($A16="",$B16=""),"", SUMIFS(Transactions!$D:$D, Transactions!$C:$C,"IN", Transactions!$L:$L,"Client", Transactions!$Q:$Q,"*Paid*", Transactions!$A:$A,">="&DATE($B16,$A16,1), Transactions!$A:$A,"<"&EDATE(DATE($B16,$A16,1),1) ) ) | D16: =IF(OR($A16="",$B16=""),"", SUMIFS(Transactions!$O:$O, Transactions!$C:$C,"IN", Transactions!$L:$L,"Client", Transactions!$Q:$Q,"*Paid*", Transactions!$A:$A,">="&DATE($B16,$A16,1), Transactions!$A:$A,"<"&EDATE(DATE($B16,$A16,1),1) ) ) | E16: =SUMIFS( Transactions!$D:$D, Transactions!$C:$C,"OUT", Transactions!$E:$E,"Cash", Transactions!$A:$A,">=" & DATE($B16,$A16,1), Transactions!$A:$A,"<" & DATE($B16,$A16+1,1) ) -> 0 | F16: =SUMIFS( Transactions!$O:$O, Transactions!$C:$C,"OUT", Transactions!$E:$E,"Cash", Transactions!$A:$A,">=" & DATE($B16,$A16,1), Transactions!$A:$A,"<" & DATE($B16,$A16+1,1) ) -> 0 | G16: =IF(OR(D16="",F16=""),"",D16-F16)

Sheet Monthly_Report
A1: Month | B1: Year | C1: Total Income (Excl. VAT) | D1: Total Expense (Excl. VAT) | E1: Net Profit / Loss | F1: Material Expense | G1: Food Expense | H1: Fuel Expense | I1: Labour Expense | J1: Transport Expense | K1: Credit Sale
A2: 11 | B2: 2025 | C2: =SUMIFS( Transactions!$D:$D, Transactions!$C:$C,"IN", Transactions!$E:$E,"Cash", Transactions!$A:$A,">=" & DATE($B2,$A2,1), Transactions!$A:$A,"<" & EOMONTH(DATE($B2,$A2,1),0)+1 ) -> 40425 | D2: =SUMIFS( Transactions!$D:$D, Transactions!$C:$C,"OUT", Transactions!$E:$E,"Cash", Transactions!$A:$A,">="&DATE($B2,$A2,1), Transactions!$A:$A,"<"&DATE($B2,$A2+1,1) ) -> 30410.05 | E2: =C2-D2 -> 10014.95 | F2: =SUMIFS( Transactions!$D:$D, Transactions!$C:$C,"OUT", Transactions!$E:$E,"Cash", Transactions!$F:$F,"Material Purchase", Transactions!$A:$A,">="&DATE($B2,$A2,1), Transactions!$A:$A,"<"&DATE($B2,$A2+1,1) ) -> 7996.7 | G2: =SUMIFS( Transactions!$D:$D, Transactions!$C:$C,"OUT", Transactions!$E:$E,"Cash", Transactions!$F:$F,"Food Expense", Transactions!$A:$A,">="&DATE($B2,$A2,1), Transactions!$A:$A,"<"&DATE($B2,$A2+1,1) ) -> 1099.99 | H2: =SUMIFS( Transactions!$D:$D, Transactions!$C:$C,"OUT", Transactions!$E:$E,"Cash", Transactions!$F:$F,"Fuel Expense", Transactions!$A:$A,">="&DATE($B2,$A2,1), Transactions!$A:$A,"<"&DATE($B2,$A2+1,1) ) -> 840.81 | I2: =SUMIFS( Transactions!$D:$D, Transactions!$C:$C,"OUT", Transactions!$E:$E,"Cash", Transactions!$F:$F,"Labour Expense", Transactions!$A:$A,">="&DATE($B2,$A2,1), Transactions!$A:$A,"<"&DATE($B2,$A2+1,1) ) -> 7382.61 | J2: =SUMIFS( Transactions!$D:$D, Transactions!$C:$C,"OUT", Transactions!$E:$E,"Cash", Transactions!$F:$F,"Transport Expense", Transactions!$A:$A,">="&DATE($B2,$A2,1), Transactions!$A:$A,"<"&DATE($B2,$A2+1,1) ) -> 1953.04 | K2: =SUMIFS( Transactions!$D:$D, Transactions!$C:$C,"IN", Transactions!$E:$E,"Accounts Receivable", Transactions!$A:$A,">=" & DATE($B2,$A2,1), Transactions!$A:$A,"<" & EOMONTH(DATE($B2,$A2,1),0)+1 ) -> 9652.5
A3: 12 | B3: 2025 | C3: =SUMIFS( Transactions!$D:$D, Transactions!$C:$C,"IN", Transactions!$E:$E,"Cash", Transactions!$A:$A,">=" & DATE($B3,$A3,1), Transactions!$A:$A,"<" & EOMONTH(DATE($B3,$A3,1),0)+1 ) -> 67827.5 | D3: =SUMIFS( Transactions!$D:$D, Transactions!$C:$C,"OUT", Transactions!$E:$E,"Cash", Transactions!$A:$A,">="&DATE($B3,$A3,1), Transactions!$A:$A,"<"&DATE($B3,$A3+1,1) ) -> 76881.28 | E3: =C3-D3 -> -9053.78 | F3: =SUMIFS( Transactions!$D:$D, Transactions!$C:$C,"OUT", Transactions!$E:$E,"Cash", Transactions!$F:$F,"Material Purchase", Transactions!$A:$A,">="&DATE($B3,$A3,1), Transactions!$A:$A,"<"&DATE($B3,$A3+1,1) ) -> 22025.95 | G3: =SUMIFS( Transactions!$D:$D, Transactions!$C:$C,"OUT", Transactions!$E:$E,"Cash", Transactions!$F:$F,"Food Expense", Transactions!$A:$A,">="&DATE($B3,$A3,1), Transactions!$A:$A,"<"&DATE($B3,$A3+1,1) ) -> 820.56 | H3: =SUMIFS( Transactions!$D:$D, Transactions!$C:$C,"OUT", Transactions!$E:$E,"Cash", Transactions!$F:$F,"Fuel Expense", Transactions!$A:$A,">="&DATE($B3,$A3,1), Transactions!$A:$A,"<"&DATE($B3,$A3+1,1) ) -> 1559.62 | I3: =SUMIFS( Transactions!$D:$D, Transactions!$C:$C,"OUT", Transactions!$E:$E,"Cash", Transactions!$F:$F,"Labour Expense", Transactions!$A:$A,">="&DATE($B3,$A3,1), Transactions!$A:$A,"<"&DATE($B3,$A3+1,1) ) -> 3500 | J3: =SUMIFS( Transactions!$D:$D, Transactions!$C:$C,"OUT", Transactions!$E:$E,"Cash", Transactions!$F:$F,"Transport Expense", Transactions!$A:$A,">="&DATE($B3,$A3,1), Transactions!$A:$A,"<"&DATE($B3,$A3+1,1) ) -> 2430 | K3: =SUMIFS( Transactions!$D:$D, Transactions!$C:$C,"IN", Transactions!$E:$E,"Accounts Receivable", Transactions!$A:$A,">=" & DATE($B3,$A3,1), Transactions!$A:$A,"<" & EOMONTH(DATE($B3,$A3,1),0)+1 ) -> 20400
A4: 1 | B4: 2026 | C4: =SUMIFS( Transactions!$D:$D, Transactions!$C:$C,"IN", Transactions!$E:$E,"Cash", Transactions!$A:$A,">=" & DATE($B4,$A4,1), Transactions!$A:$A,"<" & EOMONTH(DATE($B4,$A4,1),0)+1 ) -> 63389.57 | D4: =SUMIFS( Transactions!$D:$D, Transactions!$C:$C,"OUT", Transactions!$E:$E,"Cash", Transactions!$A:$A,">="&DATE($B4,$A4,1), Transactions!$A:$A,"<"&DATE($B4,$A4+1,1) ) -> 57420.58 | E4: =C4-D4 -> 5968.99 | F4: =SUMIFS( Transactions!$D:$D, Transactions!$C:$C,"OUT", Transactions!$E:$E,"Cash", Transactions!$F:$F,"Material Purchase", Transactions!$A:$A,">="&DATE($B4,$A4,1), Transactions!$A:$A,"<"&DATE($B4,$A4+1,1) ) -> 7401.7 | G4: =SUMIFS( Transactions!$D:$D, Transactions!$C:$C,"OUT", Transactions!$E:$E,"Cash", Transactions!$F:$F,"Food Expense", Transactions!$A:$A,">="&DATE($B4,$A4,1), Transactions!$A:$A,"<"&DATE($B4,$A4+1,1) ) -> 1900.25 | H4: =SUMIFS( Transactions!$D:$D, Transactions!$C:$C,"OUT", Transactions!$E:$E,"Cash", Transactions!$F:$F,"Fuel Expense", Transactions!$A:$A,">="&DATE($B4,$A4,1), Transactions!$A:$A,"<"&DATE($B4,$A4+1,1) ) -> 3143.52 | I4: =SUMIFS( Transactions!$D:$D, Transactions!$C:$C,"OUT", Transactions!$E:$E,"Cash", Transactions!$F:$F,"Labour Expense", Transactions!$A:$A,">="&DATE($B4,$A4,1), Transactions!$A:$A,"<"&DATE($B4,$A4+1,1) ) -> 0 | J4: =SUMIFS( Transactions!$D:$D, Transactions!$C:$C,"OUT", Transactions!$E:$E,"Cash", Transactions!$F:$F,"Transport Expense", Transactions!$A:$A,">="&DATE($B4,$A4,1), Transactions!$A:$A,"<"&DATE($B4,$A4+1,1) ) -> 700 | K4: =SUMIFS( Transactions!$D:$D, Transactions!$C:$C,"IN", Transactions!$E:$E,"Accounts Receivable", Transactions!$A:$A,">=" & DATE($B4,$A4,1), Transactions!$A:$A,"<" & EOMONTH(DATE($B4,$A4,1),0)+1 ) -> 0
A5: 2 | B5: 2026 | C5: =SUMIFS( Transactions!$D:$D, Transactions!$C:$C,"IN", Transactions!$E:$E,"Cash", Transactions!$A:$A,">=" & DATE($B5,$A5,1), Transactions!$A:$A,"<" & EOMONTH(DATE($B5,$A5,1),0)+1 ) -> 115500 | D5: =SUMIFS( Transactions!$D:$D, Transactions!$C:$C,"OUT", Transactions!$E:$E,"Cash", Transactions!$A:$A,">="&DATE($B5,$A5,1), Transactions!$A:$A,"<"&DATE($B5,$A5+1,1) ) -> 114889.18 | E5: =C5-D5 -> 610.82 | F5: =SUMIFS( Transactions!$D:$D, Transactions!$C:$C,"OUT", Transactions!$E:$E,"Cash", Transactions!$F:$F,"Material Purchase", Transactions!$A:$A,">="&DATE($B5,$A5,1), Transactions!$A:$A,"<"&DATE($B5,$A5+1,1) ) -> 30956.22 | G5: =SUMIFS( Transactions!$D:$D, Transactions!$C:$C,"OUT", Transactions!$E:$E,"Cash", Transactions!$F:$F,"Food Expense", Transactions!$A:$A,">="&DATE($B5,$A5,1), Transactions!$A:$A,"<"&DATE($B5,$A5+1,1) ) -> 777.67 | H5: =SUMIFS( Transactions!$D:$D, Transactions!$C:$C,"OUT", Transactions!$E:$E,"Cash", Transactions!$F:$F,"Fuel Expense", Transactions!$A:$A,">="&DATE($B5,$A5,1), Transactions!$A:$A,"<"&DATE($B5,$A5+1,1) ) -> 2007.77 | I5: =SUMIFS( Transactions!$D:$D, Transactions!$C:$C,"OUT", Transactions!$E:$E,"Cash", Transactions!$F:$F,"Labour Expense", Transactions!$A:$A,">="&DATE($B5,$A5,1), Transactions!$A:$A,"<"&DATE($B5,$A5+1,1) ) -> 0 | J5: =SUMIFS( Transactions!$D:$D, Transactions!$C:$C,"OUT", Transactions!$E:$E,"Cash", Transactions!$F:$F,"Transport Expense", Transactions!$A:$A,">="&DATE($B5,$A5,1), Transactions!$A:$A,"<"&DATE($B5,$A5+1,1) ) -> 210 | K5: =SUMIFS( Transactions!$D:$D, Transactions!$C:$C,"IN", Transactions!$E:$E,"Accounts Receivable", Transactions!$A:$A,">=" & DATE($B5,$A5,1), Transactions!$A:$A,"<" & EOMONTH(DATE($B5,$A5,1),0)+1 ) -> 0
A6: 3 | B6: 2026 | C6: =SUMIFS( Transactions!$D:$D, Transactions!$C:$C,"IN", Transactions!$E:$E,"Cash", Transactions!$A:$A,">=" & DATE($B6,$A6,1), Transactions!$A:$A,"<" & EOMONTH(DATE($B6,$A6,1),0)+1 ) -> 83448 | D6: =SUMIFS( Transactions!$D:$D, Transactions!$C:$C,"OUT", Transactions!$E:$E,"Cash", Transactions!$A:$A,">="&DATE($B6,$A6,1), Transactions!$A:$A,"<"&DATE($B6,$A6+1,1) ) -> 129469.78 | E6: =C6-D6 -> -46021.78 | F6: =SUMIFS( Transactions!$D:$D, Transactions!$C:$C,"OUT", Transactions!$E:$E,"Cash", Transactions!$F:$F,"Material Purchase", Transactions!$A:$A,">="&DATE($B6,$A6,1), Transactions!$A:$A,"<"&DATE($B6,$A6+1,1) ) -> 14847.36 | G6: =SUMIFS( Transactions!$D:$D, Transactions!$C:$C,"OUT", Transactions!$E:$E,"Cash", Transactions!$F:$F,"Food Expense", Transactions!$A:$A,">="&DATE($B6,$A6,1), Transactions!$A:$A,"<"&DATE($B6,$A6+1,1) ) -> 2317.89 | H6: =SUMIFS( Transactions!$D:$D, Transactions!$C:$C,"OUT", Transactions!$E:$E,"Cash", Transactions!$F:$F,"Fuel Expense", Transactions!$A:$A,">="&DATE($B6,$A6,1), Transactions!$A:$A,"<"&DATE($B6,$A6+1,1) ) -> 2328.09 | I6: =SUMIFS( Transactions!$D:$D, Transactions!$C:$C,"OUT", Transactions!$E:$E,"Cash", Transactions!$F:$F,"Labour Expense", Transactions!$A:$A,">="&DATE($B6,$A6,1), Transactions!$A:$A,"<"&DATE($B6,$A6+1,1) ) -> 0 | J6: =SUMIFS( Transactions!$D:$D, Transactions!$C:$C,"OUT", Transactions!$E:$E,"Cash", Transactions!$F:$F,"Transport Expense", Transactions!$A:$A,">="&DATE($B6,$A6,1), Transactions!$A:$A,"<"&DATE($B6,$A6+1,1) ) -> 600 | K6: =SUMIFS( Transactions!$D:$D, Transactions!$C:$C,"IN", Transactions!$E:$E,"Accounts Receivable", Transactions!$A:$A,">=" & DATE($B6,$A6,1), Transactions!$A:$A,"<" & EOMONTH(DATE($B6,$A6,1),0)+1 ) -> 0
C7: =SUMIFS( Transactions!$D:$D, Transactions!$C:$C,"IN", Transactions!$E:$E,"Cash", Transactions!$A:$A,">=" & DATE($B7,$A7,1), Transactions!$A:$A,"<" & EOMONTH(DATE($B7,$A7,1),0)+1 ) -> 0 | D7: =SUMIFS( Transactions!$D:$D, Transactions!$C:$C,"OUT", Transactions!$E:$E,"Cash", Transactions!$A:$A,">="&DATE($B7,$A7,1), Transactions!$A:$A,"<"&DATE($B7,$A7+1,1) ) -> 0 | E7: =C7-D7 -> 0 | F7: =SUMIFS( Transactions!$D:$D, Transactions!$C:$C,"OUT", Transactions!$E:$E,"Cash", Transactions!$F:$F,"Material Purchase", Transactions!$A:$A,">="&DATE($B7,$A7,1), Transactions!$A:$A,"<"&DATE($B7,$A7+1,1) ) -> 0 | G7: =SUMIFS( Transactions!$D:$D, Transactions!$C:$C,"OUT", Transactions!$E:$E,"Cash", Transactions!$F:$F,"Food Expense", Transactions!$A:$A,">="&DATE($B7,$A7,1), Transactions!$A:$A,"<"&DATE($B7,$A7+1,1) ) -> 0 | H7: =SUMIFS( Transactions!$D:$D, Transactions!$C:$C,"OUT", Transactions!$E:$E,"Cash", Transactions!$F:$F,"Fuel Expense", Transactions!$A:$A,">="&DATE($B7,$A7,1), Transactions!$A:$A,"<"&DATE($B7,$A7+1,1) ) -> 0 | I7: =SUMIFS( Transactions!$D:$D, Transactions!$C:$C,"OUT", Transactions!$E:$E,"Cash", Transactions!$F:$F,"Labour Expense", Transactions!$A:$A,">="&DATE($B7,$A7,1), Transactions!$A:$A,"<"&DATE($B7,$A7+1,1) ) -> 0 | J7: =SUMIFS( Transactions!$D:$D, Transactions!$C:$C,"OUT", Transactions!$E:$E,"Cash", Transactions!$F:$F,"Transport Expense", Transactions!$A:$A,">="&DATE($B7,$A7,1), Transactions!$A:$A,"<"&DATE($B7,$A7+1,1) ) -> 0 | K7: =SUMIFS( Transactions!$D:$D, Transactions!$C:$C,"IN", Transactions!$E:$E,"Accounts Receivable", Transactions!$A:$A,">=" & DATE($B7,$A7,1), Transactions!$A:$A,"<" & EOMONTH(DATE($B7,$A7,1),0)+1 ) -> 0
C8: =SUMIFS( Transactions!$D:$D, Transactions!$C:$C,"IN", Transactions!$E:$E,"Cash", Transactions!$A:$A,">=" & DATE($B8,$A8,1), Transactions!$A:$A,"<" & EOMONTH(DATE($B8,$A8,1),0)+1 ) -> 0 | D8: =SUMIFS( Transactions!$D:$D, Transactions!$C:$C,"OUT", Transactions!$E:$E,"Cash", Transactions!$A:$A,">="&DATE($B8,$A8,1), Transactions!$A:$A,"<"&DATE($B8,$A8+1,1) ) -> 0 | E8: =C8-D8 -> 0 | F8: =SUMIFS( Transactions!$D:$D, Transactions!$C:$C,"OUT", Transactions!$E:$E,"Cash", Transactions!$F:$F,"Material Purchase", Transactions!$A:$A,">="&DATE($B8,$A8,1), Transactions!$A:$A,"<"&DATE($B8,$A8+1,1) ) -> 0 | G8: =SUMIFS( Transactions!$D:$D, Transactions!$C:$C,"OUT", Transactions!$E:$E,"Cash", Transactions!$F:$F,"Food Expense", Transactions!$A:$A,">="&DATE($B8,$A8,1), Transactions!$A:$A,"<"&DATE($B8,$A8+1,1) ) -> 0 | H8: =SUMIFS( Transactions!$D:$D, Transactions!$C:$C,"OUT", Transactions!$E:$E,"Cash", Transactions!$F:$F,"Fuel Expense", Transactions!$A:$A,">="&DATE($B8,$A8,1), Transactions!$A:$A,"<"&DATE($B8,$A8+1,1) ) -> 0 | I8: =SUMIFS( Transactions!$D:$D, Transactions!$C:$C,"OUT", Transactions!$E:$E,"Cash", Transactions!$F:$F,"Labour Expense", Transactions!$A:$A,">="&DATE($B8,$A8,1), Transactions!$A:$A,"<"&DATE($B8,$A8+1,1) ) -> 0 | J8: =SUMIFS( Transactions!$D:$D, Transactions!$C:$C,"OUT", Transactions!$E:$E,"Cash", Transactions!$F:$F,"Transport Expense", Transactions!$A:$A,">="&DATE($B8,$A8,1), Transactions!$A:$A,"<"&DATE($B8,$A8+1,1) ) -> 0 | K8: =SUMIFS( Transactions!$D:$D, Transactions!$C:$C,"IN", Transactions!$E:$E,"Accounts Receivable", Transactions!$A:$A,">=" & DATE($B8,$A8,1), Transactions!$A:$A,"<" & EOMONTH(DATE($B8,$A8,1),0)+1 ) -> 0
C9: =SUMIFS( Transactions!$D:$D, Transactions!$C:$C,"IN", Transactions!$E:$E,"Cash", Transactions!$A:$A,">=" & DATE($B9,$A9,1), Transactions!$A:$A,"<" & EOMONTH(DATE($B9,$A9,1),0)+1 ) -> 0 | D9: =SUMIFS( Transactions!$D:$D, Transactions!$C:$C,"OUT", Transactions!$E:$E,"Cash", Transactions!$A:$A,">="&DATE($B9,$A9,1), Transactions!$A:$A,"<"&DATE($B9,$A9+1,1) ) -> 0 | E9: =C9-D9 -> 0 | F9: =SUMIFS( Transactions!$D:$D, Transactions!$C:$C,"OUT", Transactions!$E:$E,"Cash", Transactions!$F:$F,"Material Purchase", Transactions!$A:$A,">="&DATE($B9,$A9,1), Transactions!$A:$A,"<"&DATE($B9,$A9+1,1) ) -> 0 | G9: =SUMIFS( Transactions!$D:$D, Transactions!$C:$C,"OUT", Transactions!$E:$E,"Cash", Transactions!$F:$F,"Food Expense", Transactions!$A:$A,">="&DATE($B9,$A9,1), Transactions!$A:$A,"<"&DATE($B9,$A9+1,1) ) -> 0 | H9: =SUMIFS( Transactions!$D:$D, Transactions!$C:$C,"OUT", Transactions!$E:$E,"Cash", Transactions!$F:$F,"Fuel Expense", Transactions!$A:$A,">="&DATE($B9,$A9,1), Transactions!$A:$A,"<"&DATE($B9,$A9+1,1) ) -> 0 | I9: =SUMIFS( Transactions!$D:$D, Transactions!$C:$C,"OUT", Transactions!$E:$E,"Cash", Transactions!$F:$F,"Labour Expense", Transactions!$A:$A,">="&DATE($B9,$A9,1), Transactions!$A:$A,"<"&DATE($B9,$A9+1,1) ) -> 0 | J9: =SUMIFS( Transactions!$D:$D, Transactions!$C:$C,"OUT", Transactions!$E:$E,"Cash", Transactions!$F:$F,"Transport Expense", Transactions!$A:$A,">="&DATE($B9,$A9,1), Transactions!$A:$A,"<"&DATE($B9,$A9+1,1) ) -> 0 | K9: =SUMIFS( Transactions!$D:$D, Transactions!$C:$C,"IN", Transactions!$E:$E,"Accounts Receivable", Transactions!$A:$A,">=" & DATE($B9,$A9,1), Transactions!$A:$A,"<" & EOMONTH(DATE($B9,$A9,1),0)+1 ) -> 0
C10: =SUMIFS( Transactions!$D:$D, Transactions!$C:$C,"IN", Transactions!$E:$E,"Cash", Transactions!$A:$A,">=" & DATE($B10,$A10,1), Transactions!$A:$A,"<" & EOMONTH(DATE($B10,$A10,1),0)+1 ) -> 0 | D10: =SUMIFS( Transactions!$D:$D, Transactions!$C:$C,"OUT", Transactions!$E:$E,"Cash", Transactions!$A:$A,">="&DATE($B10,$A10,1), Transactions!$A:$A,"<"&DATE($B10,$A10+1,1) ) -> 0 | E10: =C10-D10 -> 0 | F10: =SUMIFS( Transactions!$D:$D, Transactions!$C:$C,"OUT", Transactions!$E:$E,"Cash", Transactions!$F:$F,"Material Purchase", Transactions!$A:$A,">="&DATE($B10,$A10,1), Transactions!$A:$A,"<"&DATE($B10,$A10+1,1) ) -> 0 | G10: =SUMIFS( Transactions!$D:$D, Transactions!$C:$C,"OUT", Transactions!$E:$E,"Cash", Transactions!$F:$F,"Food Expense", Transactions!$A:$A,">="&DATE($B10,$A10,1), Transactions!$A:$A,"<"&DATE($B10,$A10+1,1) ) -> 0 | H10: =SUMIFS( Transactions!$D:$D, Transactions!$C:$C,"OUT", Transactions!$E:$E,"Cash", Transactions!$F:$F,"Fuel Expense", Transactions!$A:$A,">="&DATE($B10,$A10,1), Transactions!$A:$A,"<"&DATE($B10,$A10+1,1) ) -> 0 | I10: =SUMIFS( Transactions!$D:$D, Transactions!$C:$C,"OUT", Transactions!$E:$E,"Cash", Transactions!$F:$F,"Labour Expense", Transactions!$A:$A,">="&DATE($B10,$A10,1), Transactions!$A:$A,"<"&DATE($B10,$A10+1,1) ) -> 0 | J10: =SUMIFS( Transactions!$D:$D, Transactions!$C:$C,"OUT", Transactions!$E:$E,"Cash", Transactions!$F:$F,"Transport Expense", Transactions!$A:$A,">="&DATE($B10,$A10,1), Transactions!$A:$A,"<"&DATE($B10,$A10+1,1) ) -> 0 | K10: =SUMIFS( Transactions!$D:$D, Transactions!$C:$C,"IN", Transactions!$E:$E,"Accounts Receivable", Transactions!$A:$A,">=" & DATE($B10,$A10,1), Transactions!$A:$A,"<" & EOMONTH(DATE($B10,$A10,1),0)+1 ) -> 0
